<?xml version="1.0" ?>
<!-- =================================================================================== -->
<!-- |    This document was autogenerated by xacro from urdf/quadruped_robot/quadruped_robot.xacro | -->
<!-- |    EDITING THIS FILE BY HAND IS NOT RECOMMENDED                                 | -->
<!-- =================================================================================== -->
<robot name="quadruped_robot">
  <material name="Red">
    <color rgba="1.0 0.0 0.0 1.0"/>
  </material>
  <material name="Green">
    <color rgba="0.0 1.0 0.0 1.0"/>
  </material>
  <material name="Blue">
    <color rgba="0.0 0.0 1.0 1.0"/>
  </material>
  <material name="Brown">
    <color rgba="0.5 0.5 0.0 1.0"/>
  </material>
  <!--////////////////////////    transmission macro    //////////////////////////-->
  <!-- <xacro:macro name="transmission_block" params="joint_name">
		<transmission name="tran1">
			<type>transmission_interface/SimpleTransmission</type>
			<joint name="${joint_name}">
				<hardwareInterface>${joint_controller_interface}</hardwareInterface>
			</joint>
			<actuator name="motor1">
				<hardwareInterface>${joint_controller_interface}</hardwareInterface>
				<mechanicalReduction>1</mechanicalReduction>
			</actuator>
		</transmission>
	</xacro:macro> -->
  <!--/////////////////////////   word link  /////////////////////////////////// -->
  <!--/////////////////////////   Body define  /////////////////////////////////// -->
  <link name="body_link">
    <visual>
      <origin rpy="0 0 0" xyz="0 0 0.0"/>
      <geometry>
        <box size="0.183 0.16 0.05"/>
      </geometry>
      <material name="Green"/>
    </visual>
    <collision>
      <origin rpy="0 0 0" xyz="0 0 0.0"/>
      <geometry>
        <box size="0.183 0.16 0.05"/>
      </geometry>
    </collision>
    <inertial>
      <origin rpy="0 0 0" xyz="0 0 0.0"/>
      <mass value="1.42"/>
      <inertia ixx="0.003325166666666667" ixy="0" ixz="0" iyy="0.004258698333333333" iyz="0" izz="0.006992198333333334"/>
    </inertial>
  </link>
  <joint name="LF1_joint" type="revolute">
    <parent link="body_link"/>
    <child link="LF1_link"/>
    <origin rpy="0 0 0" xyz="0.0915 0.08 0.0"/>
    <axis xyz="1 0 0"/>
    <limit effort="100.0" lower="-1.57" upper="1.57" velocity="300.0"/>
    <dynamics damping="0.0" friction="0.01"/>
  </joint>
  <link name="LF1_link">
    <visual>
      <origin rpy="0 0 0" xyz="0 0 -0.023"/>
      <geometry>
        <cylinder length="0.046" radius="0.01"/>
      </geometry>
      <material name="Brown"/>
    </visual>
    <collision>
      <origin rpy="0 0 0" xyz="0 0 -0.023"/>
      <geometry>
        <cylinder length="0.046" radius="0.01"/>
      </geometry>
      <surface>
        <bounce>
          <restitution_coefficient>0.5</restitution_coefficient>
          <threshold>0.001</threshold>
        </bounce>
        <friction>
          <torsional>
            <coefficient>0.6</coefficient>
            <surface_radius>0.05</surface_radius>
            <ode>
              <slip>0</slip>
            </ode>
          </torsional>
          <ode>
            <mu>0.6</mu>
            <mu2>0.6</mu2>
            <fdir1>0 0 0</fdir1>
            <slip1>0</slip1>
            <slip2>0</slip2>
          </ode>
        </friction>
        <contact>
          <ode>
            <soft_cfm>0.01</soft_cfm>
            <soft_erp>0.3</soft_erp>
            <kp value="1000000.0"/>
            <kd value="1"/>
            <max_vel>0.01</max_vel>
            <min_depth>0.001</min_depth>
          </ode>
        </contact>
      </surface>
    </collision>
    <inertial>
      <origin rpy="0 0 0" xyz="0 0 -0.023"/>
      <mass value="0.04"/>
      <inertia ixx="8.053333333333333e-06" ixy="0.0" ixz="0.0" iyy="8.053333333333333e-06" iyz="0.0" izz="2.0000000000000003e-06"/>
    </inertial>
  </link>
  <joint name="LF2_joint" type="revolute">
    <parent link="LF1_link"/>
    <child link="LF2_link"/>
    <origin rpy="0 0 0" xyz="0 0 -0.046"/>
    <axis xyz="0 1 0"/>
    <limit effort="100.0" lower="-3.14" upper="3.14" velocity="300.0"/>
    <dynamics damping="0.0" friction="0.01"/>
  </joint>
  <link name="LF2_link">
    <visual>
      <origin rpy="0 0 0" xyz="0 0 -0.033"/>
      <geometry>
        <cylinder length="0.066" radius="0.01"/>
      </geometry>
      <material name="Brown"/>
    </visual>
    <collision>
      <origin rpy="0 0 0" xyz="0 0 -0.033"/>
      <geometry>
        <cylinder length="0.066" radius="0.01"/>
      </geometry>
      <surface>
        <bounce>
          <restitution_coefficient>0.5</restitution_coefficient>
          <threshold>0.001</threshold>
        </bounce>
        <friction>
          <torsional>
            <coefficient>0.6</coefficient>
            <surface_radius>0.05</surface_radius>
            <ode>
              <slip>0</slip>
            </ode>
          </torsional>
          <ode>
            <mu>0.6</mu>
            <mu2>0.6</mu2>
            <fdir1>0 0 0</fdir1>
            <slip1>0</slip1>
            <slip2>0</slip2>
          </ode>
        </friction>
        <contact>
          <ode>
            <soft_cfm>0.01</soft_cfm>
            <soft_erp>0.3</soft_erp>
            <kp value="1000000.0"/>
            <kd value="1"/>
            <max_vel>0.01</max_vel>
            <min_depth>0.001</min_depth>
          </ode>
        </contact>
      </surface>
    </collision>
    <inertial>
      <origin rpy="0 0 0" xyz="0 0 -0.033"/>
      <mass value="0.04"/>
      <inertia ixx="1.5520000000000004e-05" ixy="0.0" ixz="0.0" iyy="1.5520000000000004e-05" iyz="0.0" izz="2.0000000000000003e-06"/>
    </inertial>
  </link>
  <joint name="LF3_joint" type="revolute">
    <parent link="LF2_link"/>
    <child link="LF3_link"/>
    <origin rpy="0 0 0" xyz="0 0 -0.066"/>
    <axis xyz="0 1 0"/>
    <limit effort="100.0" lower="-3.14" upper="3.14" velocity="300.0"/>
    <dynamics damping="0.0" friction="0.01"/>
  </joint>
  <link name="LF3_link">
    <visual>
      <origin rpy="0 0 0" xyz="0 0 -0.0325"/>
      <geometry>
        <cylinder length="0.065" radius="0.01"/>
      </geometry>
      <material name="Brown"/>
    </visual>
    <collision>
      <origin rpy="0 0 0" xyz="0 0 -0.0325"/>
      <geometry>
        <cylinder length="0.065" radius="0.01"/>
      </geometry>
      <surface>
        <bounce>
          <restitution_coefficient>0.5</restitution_coefficient>
          <threshold>0.001</threshold>
        </bounce>
        <friction>
          <torsional>
            <coefficient>0.6</coefficient>
            <surface_radius>0.05</surface_radius>
            <ode>
              <slip>0</slip>
            </ode>
          </torsional>
          <ode>
            <mu>0.6</mu>
            <mu2>0.6</mu2>
            <fdir1>0 0 0</fdir1>
            <slip1>0</slip1>
            <slip2>0</slip2>
          </ode>
        </friction>
        <contact>
          <ode>
            <soft_cfm>0.01</soft_cfm>
            <soft_erp>0.3</soft_erp>
            <kp value="1000000.0"/>
            <kd value="1"/>
            <max_vel>0.01</max_vel>
            <min_depth>0.001</min_depth>
          </ode>
        </contact>
      </surface>
    </collision>
    <inertial>
      <origin rpy="0 0 0" xyz="0 0 -0.0325"/>
      <mass value="0.04"/>
      <inertia ixx="1.5083333333333333e-05" ixy="0.0" ixz="0.0" iyy="1.5083333333333333e-05" iyz="0.0" izz="2.0000000000000003e-06"/>
    </inertial>
  </link>
  <joint name="LF4_joint" type="fixed">
    <parent link="LF3_link"/>
    <child link="LFFoot_link"/>
    <origin rpy="0 0 0" xyz="0 0 -0.065"/>
    <axis xyz="0 1 0"/>
    <limit effort="100.0" lower="-1e-05" upper="0.0" velocity="300.0"/>
    <dynamics damping="0.0" friction="0.01"/>
  </joint>
  <link name="LFFoot_link">
    <visual>
      <origin rpy="0 0 0" xyz="0 0 0"/>
      <geometry>
        <sphere radius="0.012"/>
      </geometry>
      <material name="Red"/>
    </visual>
    <collision>
      <origin rpy="0 0 0" xyz="0 0 0"/>
      <geometry>
        <sphere radius="0.012"/>
      </geometry>
    </collision>
    <inertial>
      <origin rpy="0 0 0" xyz="0 0 0"/>
      <mass value="0.04"/>
      <inertia ixx="2.304e-06" ixy="0.0" ixz="0.0" iyy="2.304e-06" iyz="0.0" izz="2.304e-06"/>
    </inertial>
  </link>
  <joint name="RF1_joint" type="revolute">
    <parent link="body_link"/>
    <child link="RF1_link"/>
    <origin rpy="0 0 0" xyz="0.0915 -0.08 0.0"/>
    <axis xyz="1 0 0"/>
    <limit effort="100.0" lower="-1.57" upper="1.57" velocity="300.0"/>
    <dynamics damping="0.0" friction="0.01"/>
  </joint>
  <link name="RF1_link">
    <visual>
      <origin rpy="0 0 0" xyz="0 0 -0.023"/>
      <geometry>
        <cylinder length="0.046" radius="0.01"/>
      </geometry>
      <material name="Brown"/>
    </visual>
    <collision>
      <origin rpy="0 0 0" xyz="0 0 -0.023"/>
      <geometry>
        <cylinder length="0.046" radius="0.01"/>
      </geometry>
      <surface>
        <bounce>
          <restitution_coefficient>0.5</restitution_coefficient>
          <threshold>0.001</threshold>
        </bounce>
        <friction>
          <torsional>
            <coefficient>0.6</coefficient>
            <surface_radius>0.05</surface_radius>
            <ode>
              <slip>0</slip>
            </ode>
          </torsional>
          <ode>
            <mu>0.6</mu>
            <mu2>0.6</mu2>
            <fdir1>0 0 0</fdir1>
            <slip1>0</slip1>
            <slip2>0</slip2>
          </ode>
        </friction>
        <contact>
          <ode>
            <soft_cfm>0.01</soft_cfm>
            <soft_erp>0.3</soft_erp>
            <kp value="1000000.0"/>
            <kd value="1"/>
            <max_vel>0.01</max_vel>
            <min_depth>0.001</min_depth>
          </ode>
        </contact>
      </surface>
    </collision>
    <inertial>
      <origin rpy="0 0 0" xyz="0 0 -0.023"/>
      <mass value="0.04"/>
      <inertia ixx="8.053333333333333e-06" ixy="0.0" ixz="0.0" iyy="8.053333333333333e-06" iyz="0.0" izz="2.0000000000000003e-06"/>
    </inertial>
  </link>
  <joint name="RF2_joint" type="revolute">
    <parent link="RF1_link"/>
    <child link="RF2_link"/>
    <origin rpy="0 0 0" xyz="0 0 -0.046"/>
    <axis xyz="0 1 0"/>
    <limit effort="100.0" lower="-3.14" upper="3.14" velocity="300.0"/>
    <dynamics damping="0.0" friction="0.01"/>
  </joint>
  <link name="RF2_link">
    <visual>
      <origin rpy="0 0 0" xyz="0 0 -0.033"/>
      <geometry>
        <cylinder length="0.066" radius="0.01"/>
      </geometry>
      <material name="Brown"/>
    </visual>
    <collision>
      <origin rpy="0 0 0" xyz="0 0 -0.033"/>
      <geometry>
        <cylinder length="0.066" radius="0.01"/>
      </geometry>
      <surface>
        <bounce>
          <restitution_coefficient>0.5</restitution_coefficient>
          <threshold>0.001</threshold>
        </bounce>
        <friction>
          <torsional>
            <coefficient>0.6</coefficient>
            <surface_radius>0.05</surface_radius>
            <ode>
              <slip>0</slip>
            </ode>
          </torsional>
          <ode>
            <mu>0.6</mu>
            <mu2>0.6</mu2>
            <fdir1>0 0 0</fdir1>
            <slip1>0</slip1>
            <slip2>0</slip2>
          </ode>
        </friction>
        <contact>
          <ode>
            <soft_cfm>0.01</soft_cfm>
            <soft_erp>0.3</soft_erp>
            <kp value="1000000.0"/>
            <kd value="1"/>
            <max_vel>0.01</max_vel>
            <min_depth>0.001</min_depth>
          </ode>
        </contact>
      </surface>
    </collision>
    <inertial>
      <origin rpy="0 0 0" xyz="0 0 -0.033"/>
      <mass value="0.04"/>
      <inertia ixx="1.5520000000000004e-05" ixy="0.0" ixz="0.0" iyy="1.5520000000000004e-05" iyz="0.0" izz="2.0000000000000003e-06"/>
    </inertial>
  </link>
  <joint name="RF3_joint" type="revolute">
    <parent link="RF2_link"/>
    <child link="RF3_link"/>
    <origin rpy="0 0 0" xyz="0 0 -0.066"/>
    <axis xyz="0 1 0"/>
    <limit effort="100.0" lower="-3.14" upper="3.14" velocity="300.0"/>
    <dynamics damping="0.0" friction="0.01"/>
  </joint>
  <link name="RF3_link">
    <visual>
      <origin rpy="0 0 0" xyz="0 0 -0.0325"/>
      <geometry>
        <cylinder length="0.065" radius="0.01"/>
      </geometry>
      <material name="Brown"/>
    </visual>
    <collision>
      <origin rpy="0 0 0" xyz="0 0 -0.0325"/>
      <geometry>
        <cylinder length="0.065" radius="0.01"/>
      </geometry>
      <surface>
        <bounce>
          <restitution_coefficient>0.5</restitution_coefficient>
          <threshold>0.001</threshold>
        </bounce>
        <friction>
          <torsional>
            <coefficient>0.6</coefficient>
            <surface_radius>0.05</surface_radius>
            <ode>
              <slip>0</slip>
            </ode>
          </torsional>
          <ode>
            <mu>0.6</mu>
            <mu2>0.6</mu2>
            <fdir1>0 0 0</fdir1>
            <slip1>0</slip1>
            <slip2>0</slip2>
          </ode>
        </friction>
        <contact>
          <ode>
            <soft_cfm>0.01</soft_cfm>
            <soft_erp>0.3</soft_erp>
            <kp value="1000000.0"/>
            <kd value="1"/>
            <max_vel>0.01</max_vel>
            <min_depth>0.001</min_depth>
          </ode>
        </contact>
      </surface>
    </collision>
    <inertial>
      <origin rpy="0 0 0" xyz="0 0 -0.0325"/>
      <mass value="0.04"/>
      <inertia ixx="1.5083333333333333e-05" ixy="0.0" ixz="0.0" iyy="1.5083333333333333e-05" iyz="0.0" izz="2.0000000000000003e-06"/>
    </inertial>
  </link>
  <joint name="RF4_joint" type="fixed">
    <parent link="RF3_link"/>
    <child link="RFFoot_link"/>
    <origin rpy="0 0 0" xyz="0 0 -0.065"/>
    <axis xyz="0 1 0"/>
    <limit effort="100.0" lower="-1e-05" upper="0.0" velocity="300.0"/>
    <dynamics damping="0.0" friction="0.01"/>
  </joint>
  <link name="RFFoot_link">
    <visual>
      <origin rpy="0 0 0" xyz="0 0 0"/>
      <geometry>
        <sphere radius="0.012"/>
      </geometry>
      <material name="Red"/>
    </visual>
    <collision>
      <origin rpy="0 0 0" xyz="0 0 0"/>
      <geometry>
        <sphere radius="0.012"/>
      </geometry>
    </collision>
    <inertial>
      <origin rpy="0 0 0" xyz="0 0 0"/>
      <mass value="0.04"/>
      <inertia ixx="2.304e-06" ixy="0.0" ixz="0.0" iyy="2.304e-06" iyz="0.0" izz="2.304e-06"/>
    </inertial>
  </link>
  <joint name="LH1_joint" type="revolute">
    <parent link="body_link"/>
    <child link="LH1_link"/>
    <origin rpy="0 0 0" xyz="-0.0915 0.08 0.0"/>
    <axis xyz="1 0 0"/>
    <limit effort="100.0" lower="-1.57" upper="1.57" velocity="300.0"/>
    <dynamics damping="0.0" friction="0.01"/>
  </joint>
  <link name="LH1_link">
    <visual>
      <origin rpy="0 0 0" xyz="0 0 -0.023"/>
      <geometry>
        <cylinder length="0.046" radius="0.01"/>
      </geometry>
      <material name="Brown"/>
    </visual>
    <collision>
      <origin rpy="0 0 0" xyz="0 0 -0.023"/>
      <geometry>
        <cylinder length="0.046" radius="0.01"/>
      </geometry>
      <surface>
        <bounce>
          <restitution_coefficient>0.5</restitution_coefficient>
          <threshold>0.001</threshold>
        </bounce>
        <friction>
          <torsional>
            <coefficient>0.6</coefficient>
            <surface_radius>0.05</surface_radius>
            <ode>
              <slip>0</slip>
            </ode>
          </torsional>
          <ode>
            <mu>0.6</mu>
            <mu2>0.6</mu2>
            <fdir1>0 0 0</fdir1>
            <slip1>0</slip1>
            <slip2>0</slip2>
          </ode>
        </friction>
        <contact>
          <ode>
            <soft_cfm>0.01</soft_cfm>
            <soft_erp>0.3</soft_erp>
            <kp value="1000000.0"/>
            <kd value="1"/>
            <max_vel>0.01</max_vel>
            <min_depth>0.001</min_depth>
          </ode>
        </contact>
      </surface>
    </collision>
    <inertial>
      <origin rpy="0 0 0" xyz="0 0 -0.023"/>
      <mass value="0.04"/>
      <inertia ixx="8.053333333333333e-06" ixy="0.0" ixz="0.0" iyy="8.053333333333333e-06" iyz="0.0" izz="2.0000000000000003e-06"/>
    </inertial>
  </link>
  <joint name="LH2_joint" type="revolute">
    <parent link="LH1_link"/>
    <child link="LH2_link"/>
    <origin rpy="0 0 0" xyz="0 0 -0.046"/>
    <axis xyz="0 1 0"/>
    <limit effort="100.0" lower="-3.14" upper="3.14" velocity="300.0"/>
    <dynamics damping="0.0" friction="0.01"/>
  </joint>
  <link name="LH2_link">
    <visual>
      <origin rpy="0 0 0" xyz="0 0 -0.033"/>
      <geometry>
        <cylinder length="0.066" radius="0.01"/>
      </geometry>
      <material name="Brown"/>
    </visual>
    <collision>
      <origin rpy="0 0 0" xyz="0 0 -0.033"/>
      <geometry>
        <cylinder length="0.066" radius="0.01"/>
      </geometry>
      <surface>
        <bounce>
          <restitution_coefficient>0.5</restitution_coefficient>
          <threshold>0.001</threshold>
        </bounce>
        <friction>
          <torsional>
            <coefficient>0.6</coefficient>
            <surface_radius>0.05</surface_radius>
            <ode>
              <slip>0</slip>
            </ode>
          </torsional>
          <ode>
            <mu>0.6</mu>
            <mu2>0.6</mu2>
            <fdir1>0 0 0</fdir1>
            <slip1>0</slip1>
            <slip2>0</slip2>
          </ode>
        </friction>
        <contact>
          <ode>
            <soft_cfm>0.01</soft_cfm>
            <soft_erp>0.3</soft_erp>
            <kp value="1000000.0"/>
            <kd value="1"/>
            <max_vel>0.01</max_vel>
            <min_depth>0.001</min_depth>
          </ode>
        </contact>
      </surface>
    </collision>
    <inertial>
      <origin rpy="0 0 0" xyz="0 0 -0.033"/>
      <mass value="0.04"/>
      <inertia ixx="1.5520000000000004e-05" ixy="0.0" ixz="0.0" iyy="1.5520000000000004e-05" iyz="0.0" izz="2.0000000000000003e-06"/>
    </inertial>
  </link>
  <joint name="LH3_joint" type="revolute">
    <parent link="LH2_link"/>
    <child link="LH3_link"/>
    <origin rpy="0 0 0" xyz="0 0 -0.066"/>
    <axis xyz="0 1 0"/>
    <limit effort="100.0" lower="-3.14" upper="3.14" velocity="300.0"/>
    <dynamics damping="0.0" friction="0.01"/>
  </joint>
  <link name="LH3_link">
    <visual>
      <origin rpy="0 0 0" xyz="0 0 -0.0325"/>
      <geometry>
        <cylinder length="0.065" radius="0.01"/>
      </geometry>
      <material name="Brown"/>
    </visual>
    <collision>
      <origin rpy="0 0 0" xyz="0 0 -0.0325"/>
      <geometry>
        <cylinder length="0.065" radius="0.01"/>
      </geometry>
      <surface>
        <bounce>
          <restitution_coefficient>0.5</restitution_coefficient>
          <threshold>0.001</threshold>
        </bounce>
        <friction>
          <torsional>
            <coefficient>0.6</coefficient>
            <surface_radius>0.05</surface_radius>
            <ode>
              <slip>0</slip>
            </ode>
          </torsional>
          <ode>
            <mu>0.6</mu>
            <mu2>0.6</mu2>
            <fdir1>0 0 0</fdir1>
            <slip1>0</slip1>
            <slip2>0</slip2>
          </ode>
        </friction>
        <contact>
          <ode>
            <soft_cfm>0.01</soft_cfm>
            <soft_erp>0.3</soft_erp>
            <kp value="1000000.0"/>
            <kd value="1"/>
            <max_vel>0.01</max_vel>
            <min_depth>0.001</min_depth>
          </ode>
        </contact>
      </surface>
    </collision>
    <inertial>
      <origin rpy="0 0 0" xyz="0 0 -0.0325"/>
      <mass value="0.04"/>
      <inertia ixx="1.5083333333333333e-05" ixy="0.0" ixz="0.0" iyy="1.5083333333333333e-05" iyz="0.0" izz="2.0000000000000003e-06"/>
    </inertial>
  </link>
  <joint name="LH4_joint" type="fixed">
    <parent link="LH3_link"/>
    <child link="LHFoot_link"/>
    <origin rpy="0 0 0" xyz="0 0 -0.065"/>
    <axis xyz="0 1 0"/>
    <limit effort="100.0" lower="-1e-05" upper="0.0" velocity="300.0"/>
    <dynamics damping="0.0" friction="0.01"/>
  </joint>
  <link name="LHFoot_link">
    <visual>
      <origin rpy="0 0 0" xyz="0 0 0"/>
      <geometry>
        <sphere radius="0.012"/>
      </geometry>
      <material name="Red"/>
    </visual>
    <collision>
      <origin rpy="0 0 0" xyz="0 0 0"/>
      <geometry>
        <sphere radius="0.012"/>
      </geometry>
    </collision>
    <inertial>
      <origin rpy="0 0 0" xyz="0 0 0"/>
      <mass value="0.04"/>
      <inertia ixx="2.304e-06" ixy="0.0" ixz="0.0" iyy="2.304e-06" iyz="0.0" izz="2.304e-06"/>
    </inertial>
  </link>
  <joint name="RH1_joint" type="revolute">
    <parent link="body_link"/>
    <child link="RH1_link"/>
    <origin rpy="0 0 0" xyz="-0.0915 -0.08 0.0"/>
    <axis xyz="1 0 0"/>
    <limit effort="100.0" lower="-1.57" upper="1.57" velocity="300.0"/>
    <dynamics damping="0.0" friction="0.01"/>
  </joint>
  <link name="RH1_link">
    <visual>
      <origin rpy="0 0 0" xyz="0 0 -0.023"/>
      <geometry>
        <cylinder length="0.046" radius="0.01"/>
      </geometry>
      <material name="Brown"/>
    </visual>
    <collision>
      <origin rpy="0 0 0" xyz="0 0 -0.023"/>
      <geometry>
        <cylinder length="0.046" radius="0.01"/>
      </geometry>
      <surface>
        <bounce>
          <restitution_coefficient>0.5</restitution_coefficient>
          <threshold>0.001</threshold>
        </bounce>
        <friction>
          <torsional>
            <coefficient>0.6</coefficient>
            <surface_radius>0.05</surface_radius>
            <ode>
              <slip>0</slip>
            </ode>
          </torsional>
          <ode>
            <mu>0.6</mu>
            <mu2>0.6</mu2>
            <fdir1>0 0 0</fdir1>
            <slip1>0</slip1>
            <slip2>0</slip2>
          </ode>
        </friction>
        <contact>
          <ode>
            <soft_cfm>0.01</soft_cfm>
            <soft_erp>0.3</soft_erp>
            <kp value="1000000.0"/>
            <kd value="1"/>
            <max_vel>0.01</max_vel>
            <min_depth>0.001</min_depth>
          </ode>
        </contact>
      </surface>
    </collision>
    <inertial>
      <origin rpy="0 0 0" xyz="0 0 -0.023"/>
      <mass value="0.04"/>
      <inertia ixx="8.053333333333333e-06" ixy="0.0" ixz="0.0" iyy="8.053333333333333e-06" iyz="0.0" izz="2.0000000000000003e-06"/>
    </inertial>
  </link>
  <joint name="RH2_joint" type="revolute">
    <parent link="RH1_link"/>
    <child link="RH2_link"/>
    <origin rpy="0 0 0" xyz="0 0 -0.046"/>
    <axis xyz="0 1 0"/>
    <limit effort="100.0" lower="-3.14" upper="3.14" velocity="300.0"/>
    <dynamics damping="0.0" friction="0.01"/>
  </joint>
  <link name="RH2_link">
    <visual>
      <origin rpy="0 0 0" xyz="0 0 -0.033"/>
      <geometry>
        <cylinder length="0.066" radius="0.01"/>
      </geometry>
      <material name="Brown"/>
    </visual>
    <collision>
      <origin rpy="0 0 0" xyz="0 0 -0.033"/>
      <geometry>
        <cylinder length="0.066" radius="0.01"/>
      </geometry>
      <surface>
        <bounce>
          <restitution_coefficient>0.5</restitution_coefficient>
          <threshold>0.001</threshold>
        </bounce>
        <friction>
          <torsional>
            <coefficient>0.6</coefficient>
            <surface_radius>0.05</surface_radius>
            <ode>
              <slip>0</slip>
            </ode>
          </torsional>
          <ode>
            <mu>0.6</mu>
            <mu2>0.6</mu2>
            <fdir1>0 0 0</fdir1>
            <slip1>0</slip1>
            <slip2>0</slip2>
          </ode>
        </friction>
        <contact>
          <ode>
            <soft_cfm>0.01</soft_cfm>
            <soft_erp>0.3</soft_erp>
            <kp value="1000000.0"/>
            <kd value="1"/>
            <max_vel>0.01</max_vel>
            <min_depth>0.001</min_depth>
          </ode>
        </contact>
      </surface>
    </collision>
    <inertial>
      <origin rpy="0 0 0" xyz="0 0 -0.033"/>
      <mass value="0.04"/>
      <inertia ixx="1.5520000000000004e-05" ixy="0.0" ixz="0.0" iyy="1.5520000000000004e-05" iyz="0.0" izz="2.0000000000000003e-06"/>
    </inertial>
  </link>
  <joint name="RH3_joint" type="revolute">
    <parent link="RH2_link"/>
    <child link="RH3_link"/>
    <origin rpy="0 0 0" xyz="0 0 -0.066"/>
    <axis xyz="0 1 0"/>
    <limit effort="100.0" lower="-3.14" upper="3.14" velocity="300.0"/>
    <dynamics damping="0.0" friction="0.01"/>
  </joint>
  <link name="RH3_link">
    <visual>
      <origin rpy="0 0 0" xyz="0 0 -0.0325"/>
      <geometry>
        <cylinder length="0.065" radius="0.01"/>
      </geometry>
      <material name="Brown"/>
    </visual>
    <collision>
      <origin rpy="0 0 0" xyz="0 0 -0.0325"/>
      <geometry>
        <cylinder length="0.065" radius="0.01"/>
      </geometry>
      <surface>
        <bounce>
          <restitution_coefficient>0.5</restitution_coefficient>
          <threshold>0.001</threshold>
        </bounce>
        <friction>
          <torsional>
            <coefficient>0.6</coefficient>
            <surface_radius>0.05</surface_radius>
            <ode>
              <slip>0</slip>
            </ode>
          </torsional>
          <ode>
            <mu>0.6</mu>
            <mu2>0.6</mu2>
            <fdir1>0 0 0</fdir1>
            <slip1>0</slip1>
            <slip2>0</slip2>
          </ode>
        </friction>
        <contact>
          <ode>
            <soft_cfm>0.01</soft_cfm>
            <soft_erp>0.3</soft_erp>
            <kp value="1000000.0"/>
            <kd value="1"/>
            <max_vel>0.01</max_vel>
            <min_depth>0.001</min_depth>
          </ode>
        </contact>
      </surface>
    </collision>
    <inertial>
      <origin rpy="0 0 0" xyz="0 0 -0.0325"/>
      <mass value="0.04"/>
      <inertia ixx="1.5083333333333333e-05" ixy="0.0" ixz="0.0" iyy="1.5083333333333333e-05" iyz="0.0" izz="2.0000000000000003e-06"/>
    </inertial>
  </link>
  <joint name="RH4_joint" type="fixed">
    <parent link="RH3_link"/>
    <child link="RHFoot_link"/>
    <origin rpy="0 0 0" xyz="0 0 -0.065"/>
    <axis xyz="0 1 0"/>
    <limit effort="100.0" lower="-1e-05" upper="0.0" velocity="300.0"/>
    <dynamics damping="0.0" friction="0.01"/>
  </joint>
  <link name="RHFoot_link">
    <visual>
      <origin rpy="0 0 0" xyz="0 0 0"/>
      <geometry>
        <sphere radius="0.012"/>
      </geometry>
      <material name="Red"/>
    </visual>
    <collision>
      <origin rpy="0 0 0" xyz="0 0 0"/>
      <geometry>
        <sphere radius="0.012"/>
      </geometry>
    </collision>
    <inertial>
      <origin rpy="0 0 0" xyz="0 0 0"/>
      <mass value="0.04"/>
      <inertia ixx="2.304e-06" ixy="0.0" ixz="0.0" iyy="2.304e-06" iyz="0.0" izz="2.304e-06"/>
    </inertial>
  </link>
  <!--////////////////////////    tansmission define   //////////////////////////-->
  <!-- 
	<xacro:transmission_block joint_name="LF1_joint"/>
   	<xacro:transmission_block joint_name="LF2_joint"/>
   	<xacro:transmission_block joint_name="LF3_joint"/>
	<xacro:transmission_block joint_name="RF1_joint"/>
	<xacro:transmission_block joint_name="RF2_joint"/>
	<xacro:transmission_block joint_name="RF3_joint"/>
	<xacro:transmission_block joint_name="LH1_joint"/>
	<xacro:transmission_block joint_name="LH2_joint"/>
	<xacro:transmission_block joint_name="LH3_joint"/>
	<xacro:transmission_block joint_name="RH1_joint"/>
	<xacro:transmission_block joint_name="RH2_joint"/>
	<xacro:transmission_block joint_name="RH3_joint"/> -->
</robot>

